Workbook

Sheet Basic
C1: Model 고정: Deepsurvk_Layer5
N2: Evaluation
B3: 번호 | C3: Index | D3: Data | I3: Hyper Parameter | L3: FL Parameter | N3: C-index | O3: IBS | P3: tAUC
D4: Type | E4: Evn | F4: Client | G4: Train | H4: Test | I4: Epoch | J4: Batch | K4: Model | L4: Round | M4: Aggregation | N4: Test | O4: Test | P4: Test
B5: 1 | C5: Centralized Model | D5: Clinical | E5: - | F5: - | G5: 3000x20 | H5: 600x20 | I5: 200 | J5: Full Batch | K5: DeepsurvK | L5: - | M5: - | N5: 0.734 | O5: 0.221 | P5: 0.808
B6: 2 | C6: Centralized Model | D6: Clinical | E6: - | F6: - | G6: 3000x10 | H6: 600x10 | I6: 3000 | J6: 64 | K6: SAVAE | L6: - | M6: - | N6: 0.712 | O6: 0.13
B7: 3 | C7: Centralized Model | D7: Clinical | E7: - | F7: - | G7: 3000x20 | H7: 600x20 | I7: 3000 | J7: 64 | K7: SAVAE | L7: - | M7: - | N7: 0.728 | O7: 0.133
B8: 2 | C8: Centralized Model | D8: Clinical | E8: Env1 (IID) | F8: 1 | G8: 300x20 | H8: 600x20 | I8: 200 | J8: Full Batch | K8: DeepsurvK | L8: - | M8: - | N8: 0.723 | O8: 0.221 | P8: 0.793
F9: 2 | G9: 300x20 | N9: 0.738 | O9: 0.221 | P9: 0.808
F10: 3 | G10: 300x20 | N10: 0.705 | O10: 0.221 | P10: 0.761
F11: 4 | G11: 300x20 | N11: 0.658 | O11: 0.222 | P11: 0.722
F12: 5 | G12: 300x20 | N12: 0.684 | O12: 0.221 | P12: 0.73
F13: 6 | G13: 300x20 | N13: 0.698 | O13: 0.221 | P13: 0.774
F14: 7 | G14: 300x20 | N14: 0.722 | O14: 0.221 | P14: 0.79
F15: 8 | G15: 300x20 | N15: 0.644 | O15: 0.221 | P15: 0.704
F16: 9 | G16: 300x20 | N16: 0.658 | O16: 0.221 | P16: 0.695
F17: 10 | G17: 300x20 | N17: 0.694 | O17: 0.221 | P17: 0.748
N18: =AVERAGE(N8:N17) -> 0.6924 | O18: =AVERAGE(O8:O17) -> 0.2211 | P18: =AVERAGE(P8:P17) -> 0.7525
B19: 3 | C19: Centralized Model | D19: Clinical | E19: Env2 (NonIID, FeatureSkew-Overall.stage) | F19: 1 | H19: 600x20 | I19: 200 | J19: Full Batch | K19: DeepsurvK | L19: - | M19: -
F20: 2
F21: 3
F22: 4
F23: 5
F24: 6
F25: 7
F26: 8
F27: 9
F28: 10
N29: =AVERAGE(N19:N28) -> #DIV/0! | O29: =AVERAGE(O19:O28) -> #DIV/0! | P29: =AVERAGE(P19:P28) -> #DIV/0!
B30: 4 | C30: Centralized Model | D30: Clinical | E30: Env3 (NonIID, LabelSkew-Deadstatus.event) | F30: 1 | H30: 600x20 | I30: 200 | J30: Full Batch | K30: DeepsurvK | L30: - | M30: -
A31: i | F31: 2
F32: 3
F33: 4
F34: 5
F35: 6
F36: 7
F37: 8
F38: 9
F39: 10
N40: =AVERAGE(N30:N39) -> #DIV/0! | O40: =AVERAGE(O30:O39) -> #DIV/0! | P40: =AVERAGE(P30:P39) -> #DIV/0!
...

Sheet FedAvg
B2: Round | C2: Environment | E2: Data | G2: Hyper Parameter | I2: Evaluation | L2: Client-1 | O2: Client-2 | R2: Client-3 | U2: Client-4 | X2: Client-5 | AA2: Client-6 | AD2: Client-7 | AG2: Client-8 | AJ2: Client-9 | AM2: Client-10
C3: env | D3: aggregator | E3: test | F3: features | G3: epoch | H3: round | I3: c-index | J3: IBS | K3: mAUC | L3: c-index | M3: IBS | N3: mAUC | O3: c-index | P3: IBS | Q3: mAUC | R3: c-index | S3: IBS | T3: mAUC | U3: c-index | V3: IBS | W3: mAUC | X3: c-index | Y3: IBS | Z3: mAUC | AA3: c-index | AB3: IBS | AC3: mAUC | AD3: c-index | AE3: IBS | AF3: mAUC | AG3: c-index | AH3: IBS | AI3: mAUC | AJ3: c-index | AK3: IBS | AL3: mAUC | AM3: c-index | AN3: IBS | AO3: mAUC
B4: 1 | C4: Env1 (IID) | D4: fedavg | E4: 600 | F4: 20 | G4: 200 | H4: 10 | I4: 0.68034261 | J4: 0.2170017 | K4: 0.73812751 | L4: 0.68687495 | M4: 0.18694021 | N4: 0.74268486 | O4: 0.67473521 | P4: 0.18907484 | Q4: 0.74016714 | R4: 0.7066229 | S4: 0.1769902 | T4: 0.76758712 | U4: 0.66590659 | V4: 0.19250518 | W4: 0.71111345 | X4: 0.71387142 | Y4: 0.17212064 | Z4: 0.77973105 | AA4: 0.70091594 | AB4: 0.1755299 | AC4: 0.76885389 | AD4: 0.6953535 | AE4: 0.18240103 | AF4: 0.76191479 | AG4: 0.68384644 | AH4: 0.18503724 | AI4: 0.74212088 | AJ4: 0.7062889 | AK4: 0.17346248 | AL4: 0.77138405 | AM4: 0.69302511 | AN4: 0.17985305 | AO4: 0.75069506
B5: 2 | I5: 0.70910866 | J5: 0.17828549 | K5: 0.77842146 | L5: 0.69410098 | M5: 0.18266132 | N5: 0.75185546 | O5: 0.71655951 | P5: 0.1767477 | Q5: 0.78201086 | R5: 0.71544509 | S5: 0.17428792 | T5: 0.78308019 | U5: 0.6754 | V5: 0.18183657 | W5: 0.72445456 | X5: 0.70494325 | Y5: 0.17648637 | Z5: 0.76220511 | AA5: 0.72832028 | AB5: 0.16626127 | AC5: 0.80109112 | AD5: 0.71606814 | AE5: 0.17254155 | AF5: 0.78259836 | AG5: 0.69828566 | AH5: 0.17523923 | AI5: 0.7598976 | AJ5: 0.70063653 | AK5: 0.18368403 | AL5: 0.76824335 | AM5: 0.70779513 | AN5: 0.17802047 | AO5: 0.76997948
B6: 3 | I6: 0.70812271 | J6: 0.18016143 | K6: 0.77689763 | L6: 0.68621015 | M6: 0.18090066 | N6: 0.75172163 | O6: 0.70158716 | P6: 0.18167056 | Q6: 0.76619332 | R6: 0.71152376 | S6: 0.1759097 | T6: 0.77862629 | U6: 0.68122579 | V6: 0.18293013 | W6: 0.73970121 | X6: 0.71901957 | Y6: 0.17087674 | Z6: 0.78291756 | AA6: 0.69323707 | AB6: 0.17957368 | AC6: 0.75890229 | AD6: 0.70715924 | AE6: 0.17616925 | AF6: 0.77250966 | AG6: 0.67621574 | AH6: 0.18134013 | AI6: 0.7270628 | AJ6: 0.69764656 | AK6: 0.18169731 | AL6: 0.75952885 | AM6: 0.68123864 | AN6: 0.18290316 | AO6: 0.72849034
B7: 4 | I7: 0.70070719 | J7: 0.17915705 | K7: 0.7657887 | L7: 0.67098088 | M7: 0.18374342 | N7: 0.73023584 | O7: 0.69042373 | P7: 0.18034871 | Q7: 0.7571639 | R7: 0.71166828 | S7: 0.17332883 | T7: 0.77340974 | U7: 0.67046703 | V7: 0.17867251 | W7: 0.71801667 | X7: 0.69053293 | Y7: 0.17628423 | Z7: 0.74762128 | AA7: 0.68940245 | AB7: 0.18036109 | AC7: 0.7497537 | AD7: 0.70442298 | AE7: 0.17209015 | AF7: 0.76041911 | AG7: 0.69928767 | AH7: 0.17933845 | AI7: 0.7581255 | AJ7: 0.68225671 | AK7: 0.18300594 | AL7: 0.74016261 | AM7: 0.66122091 | AN7: 0.18416903 | AO7: 0.72062106
B8: 5 | I8: 0.70797498 | J8: 0.176108 | K8: 0.77002628 | L8: 0.68065092 | M8: 0.17831107 | N8: 0.73098236 | O8: 0.70689589 | P8: 0.18204867 | Q8: 0.7643291 | R8: 0.72283171 | S8: 0.16569867 | T8: 0.7799197 | U8: 0.65289009 | V8: 0.18138197 | W8: 0.69553653 | X8: 0.68437313 | Y8: 0.17994324 | Z8: 0.73813071 | AA8: 0.70363935 | AB8: 0.17750612 | AC8: 0.76290067 | AD8: 0.69540167 | AE8: 0.18070625 | AF8: 0.7554 | AG8: 0.68807286 | AH8: 0.17998611 | AI8: 0.74191123 | AJ8: 0.68291508 | AK8: 0.17686666 | AL8: 0.73923815 | AM8: 0.6844181 | AN8: 0.18208211 | AO8: 0.74122602
B9: 6 | I9: 0.68916159 | J9: 0.17855783 | K9: 0.74413091 | L9: 0.59214963 | M9: 0.19836195 | N9: 0.60932085 | O9: 0.68788338 | P9: 0.18154423 | Q9: 0.74458136 | R9: 0.69518328 | S9: 0.17566117 | T9: 0.7525164 | U9: 0.66871672 | V9: 0.18254758 | W9: 0.72329973 | X9: 0.70350768 | Y9: 0.17204909 | Z9: 0.76073882 | AA9: 0.70611548 | AB9: 0.17442657 | AC9: 0.76469157 | AD9: 0.69069351 | AE9: 0.17502893 | AF9: 0.7450289 | AG9: 0.62559816 | AH9: 0.19256141 | AI9: 0.65379737 | AJ9: 0.6914675 | AK9: 0.17272914 | AL9: 0.745761 | AM9: 0.69924592 | AN9: 0.17812826 | AO9: 0.75391934
B10: 7 | I10: 0.69197492 | J10: 0.17698275 | K10: 0.74736191 | L10: 0.69129086 | M10: 0.17876766 | N10: 0.74580239 | O10: 0.67982876 | P10: 0.18093204 | Q10: 0.74004867 | R10: 0.68372761 | S10: 0.17280315 | T10: 0.72773654 | U10: 0.65454084 | V10: 0.18556244 | W10: 0.69891147 | X10: 0.68673364 | Y10: 0.17661498 | Z10: 0.7388781 | AA10: 0.65958622 | AB10: 0.18617222 | AC10: 0.69637063 | AD10: 0.7059549 | AE10: 0.17266151 | AF10: 0.76384986 | AG10: 0.69328846 | AH10: 0.1734766 | AI10: 0.7476004 | AJ10: 0.68649277 | AK10: 0.1774883 | AL10: 0.74016662 | AM10: 0.69324349 | AN10: 0.17257085 | AO10: 0.74405232
B11: 8 | I11: 0.68893678 | J11: 0.18209769 | K11: 0.7438736 | L11: 0.66753165 | M11: 0.18140981 | N11: 0.71085962 | O11: 0.67775408 | P11: 0.17403426 | Q11: 0.72676673 | R11: 0.65652559 | S11: 0.18368448 | T11: 0.69401492 | U11: 0.67070147 | V11: 0.17935202 | W11: 0.71940438 | X11: 0.68388176 | Y11: 0.1773281 | Z11: 0.73411775 | AA11: 0.67587853 | AB11: 0.18303625 | AC11: 0.72404813 | AD11: 0.6948268 | AE11: 0.17906661 | AF11: 0.75382262 | AG11: 0.68405198 | AH11: 0.17759553 | AI11: 0.73107325 | AJ11: 0.67362721 | AK11: 0.17870077 | AL11: 0.72561124 | AM11: 0.7028461 | AN11: 0.17630415 | AO11: 0.75966652
B12: 9 | I12: 0.68452408 | J12: 0.18067719 | K12: 0.7395092 | L12: 0.69329488 | M12: 0.17963164 | N12: 0.74299254 | O12: 0.67700258 | P12: 0.17852384 | Q12: 0.73004726 | R12: 0.68552288 | S12: 0.17560664 | T12: 0.73251967 | U12: 0.66406958 | V12: 0.17830349 | W12: 0.70337832 | X12: 0.66391542 | Y12: 0.18038572 | Z12: 0.70175268 | AA12: 0.65723214 | AB12: 0.18069067 | AC12: 0.69349222 | AD12: 0.67779262 | AE12: 0.18213979 | AF12: 0.72800131 | AG12: 0.67798532 | AH12: 0.1789123 | AI12: 0.72388834 | AJ12: 0.67712462 | AK12: 0.17913173 | AL12: 0.72799804 | AM12: 0.6533076 | AN12: 0.1885928 | AO12: 0.70145954
B13: 10 | I13: 0.68253611 | J13: 0.18094204 | K13: 0.73221769 | L13: 0.64041956 | M13: 0.18827328 | N13: 0.67274675 | O13: 0.67434339 | P13: 0.18253959 | Q13: 0.7231856 | R13: 0.69552692 | S13: 0.17274312 | T13: 0.74379061 | U13: 0.66765048 | V13: 0.18446455 | W13: 0.71929908 | X13: 0.68806644 | Y13: 0.17168265 | Z13: 0.73333776 | AA13: 0.66290056 | AB13: 0.18428175 | AC13: 0.7008083 | AD13: 0.6447873 | AE13: 0.18782776 | AF13: 0.67883401 | AG13: 0.63749703 | AH13: 0.18753163 | AI13: 0.67140484 | AJ13: 0.67159108 | AK13: 0.18029638 | AL13: 0.7143588 | AM13: 0.68187774 | AN13: 0.17907466 | AO13: 0.72897169
B14: 1 | C14: Env2 (NonIID, FeatureSkew-Overall.stage) | D14: fedavg | E14: 600 | F14: 20 | G14: 200 | H14: 10 | I14: 0.54674122 | J14: 0.22141911 | K14: 0.56061968 | L14: 0.69652893 | M14: 0.17981883 | N14: 0.74900016 | O14: 0.66563682 | P14: 0.19979693 | Q14: 0.73040885 | R14: 0.60373699 | S14: 0.21805697 | T14: 0.64736156 | U14: 0.66033773 | V14: 0.21388292 | W14: 0.71230393 | X14: 0.70249603 | Y14: 0.18136004 | Z14: 0.76297769 | AA14: 0.67000777 | AB14: 0.19816347 | AC14: 0.72613765 | AD14: 0.68476495 | AE14: 0.19820383 | AF14: 0.75363349 | AG14: 0.64376602 | AH14: 0.21681827 | AI14: 0.70536992 | AJ14: 0.68298895 | AK14: 0.18825297 | AL14: 0.7263848 | AM14: 0.60461053 | AN14: 0.24660976 | AO14: 0.64431189
B15: 2 | I15: 0.6967152 | J15: 0.18818558 | K15: 0.77076006 | L15: 0.71268635 | M15: 0.17733572 | N15: 0.76967164 | O15: 0.6832812 | P15: 0.19404895 | Q15: 0.75462889 | R15: 0.66452883 | S15: 0.19967065 | T15: 0.72483318 | U15: 0.68443736 | V15: 0.19501092 | W15: 0.7494759 | X15: 0.71386821 | Y15: 0.19264934 | Z15: 0.77583274 | AA15: 0.68035225 | AB15: 0.18814039 | AC15: 0.73331491 | AD15: 0.68086289 | AE15: 0.19419322 | AF15: 0.74741306 | AG15: 0.69961204 | AH15: 0.194496 | AI15: 0.7690795 | AJ15: 0.68206722 | AK15: 0.18255592 | AL15: 0.73005022 | AM15: 0.60697746 | AN15: 0.24289448 | AO15: 0.66216378
B16: 3 | I16: 0.68212182 | J16: 0.18246231 | K16: 0.73792311 | L16: 0.70722668 | M16: 0.17401406 | N16: 0.76182891 | O16: 0.69706205 | P16: 0.18774135 | Q16: 0.76756543 | R16: 0.63967769 | S16: 0.20404939 | T16: 0.69333651 | U16: 0.64253277 | V16: 0.20194223 | W16: 0.6992364 | X16: 0.72618138 | Y16: 0.16811809 | Z16: 0.78959952 | AA16: 0.62849178 | AB16: 0.19443351 | AC16: 0.67588875 | AD16: 0.68975252 | AE16: 0.18771919 | AF16: 0.76771139 | AG16: 0.66216511 | AH16: 0.21361242 | AI16: 0.74102911 | AJ16: 0.67265411 | AK16: 0.18707664 | AL16: 0.70937092 | AM16: 0.66780463 | AN16: 0.20425264 | AO16: 0.72216108
B17: 4 | I17: 0.66015146 | J17: 0.18544983 | K17: 0.70367632 | L17: 0.6959926 | M17: 0.18931649 | N17: 0.74221059 | O17: 0.69338802 | P17: 0.1846164 | Q17: 0.76657068 | R17: 0.66800054 | S17: 0.19443358 | T17: 0.72546975 | U17: 0.65418115 | V17: 0.2011369 | W17: 0.7126626 | X17: 0.7302954 | Y17: 0.17166688 | Z17: 0.79497273 | AA17: 0.63403817 | AB17: 0.1972473 | AC17: 0.68118464 | AD17: 0.69886053 | AE17: 0.1874168 | AF17: 0.77415126 | AG17: 0.69468228 | AH17: 0.19729495 | AI17: 0.76358847 | AJ17: 0.67832574 | AK17: 0.1928499 | AL17: 0.72510992 | AM17: 0.6638255 | AN17: 0.20764809 | AO17: 0.72161173
B18: 5 | I18: 0.68578944 | J18: 0.1865744 | K18: 0.74185336 | L18: 0.71290795 | M18: 0.1823831 | N18: 0.77267925 | O18: 0.71521386 | P18: 0.17491213 | Q18: 0.78332816 | R18: 0.66942005 | S18: 0.18963612 | T18: 0.7236391 | U18: 0.66769544 | V18: 0.20494087 | W18: 0.7246715 | X18: 0.70889027 | Y18: 0.18396818 | Z18: 0.76194162 | AA18: 0.66762479 | AB18: 0.19244152 | AC18: 0.72131597 | AD18: 0.68413869 | AE18: 0.19177102 | AF18: 0.74080667 | AG18: 0.70383847 | AH18: 0.20147342 | AI18: 0.78016655 | AJ18: 0.66214584 | AK18: 0.18677723 | AL18: 0.69767869 | AM18: 0.67794999 | AN18: 0.20854824 | AO18: 0.74133962
B19: 6 | I19: 0.6785634 | J19: 0.18571693 | K19: 0.73216161 | L19: 0.66018679 | M19: 0.18769001 | N19: 0.69470793 | O19: 0.65262353 | P19: 0.19085246 | Q19: 0.69484519 | R19: 0.65717112 | S19: 0.19292978 | T19: 0.70102903 | U19: 0.65693989 | V19: 0.20114529 | W19: 0.7118125 | X19: 0.65640998 | Y19: 0.19453264 | Z19: 0.69357827 | AA19: 0.67122817 | AB19: 0.18536377 | AC19: 0.71506092 | AD19: 0.65632969 | AE19: 0.19451547 | AF19: 0.71189111 | AG19: 0.6846686 | AH19: 0.19426074 | AI19: 0.75313404 | AJ19: 0.67003346 | AK19: 0.17979918 | AL19: 0.71168476 | AM19: 0.68085004 | AN19: 0.21008462 | AO19: 0.73346885
B20: 7 | I20: 0.68204153 | J20: 0.18745893 | K20: 0.73850301 | L20: 0.6671559 | M20: 0.18261246 | N20: 0.7094387 | O20: 0.66192425 | P20: 0.18548179 | Q20: 0.70804717 | R20: 0.65860669 | S20: 0.19119238 | T20: 0.70970739 | U20: 0.64380135 | V20: 0.21885478 | W20: 0.70068516 | X20: 0.6876104 | Y20: 0.18688939 | Z20: 0.73373851 | AA20: 0.67430486 | AB20: 0.18362648 | AC20: 0.72945684 | AD20: 0.67441084 | AE20: 0.19283199 | AF20: 0.7281608 | AG20: 0.64811127 | AH20: 0.20739604 | AI20: 0.72085228 | AJ20: 0.67374283 | AK20: 0.19024554 | AL20: 0.72133357 | AM20: 0.67175166 | AN20: 0.20801497 | AO20: 0.72222552
B21: 8 | I21: 0.68463327 | J21: 0.18117075 | K21: 0.74311745 | L21: 0.67325467 | M21: 0.19026045 | N21: 0.72494719 | O21: 0.69616281 | P21: 0.18041024 | Q21: 0.75430975 | R21: 0.66735823 | S21: 0.19159033 | T21: 0.71856518 | U21: 0.65537585 | V21: 0.19439385 | W21: 0.70725258 | X21: 0.65654165 | Y21: 0.19415781 | Z21: 0.70109063 | AA21: 0.64050627 | AB21: 0.18649622 | AC21: 0.66976927 | AD21: 0.6778697 | AE21: 0.18947228 | AF21: 0.73783226 | AG21: 0.67035141 | AH21: 0.18894137 | AI21: 0.73720014 | AJ21: 0.63510762 | AK21: 0.19831986 | AL21: 0.6659485 | AM21: 0.66780785 | AN21: 0.20473226 | AO21: 0.72797912
B22: 9 | I22: 0.67888777 | J22: 0.17927926 | K22: 0.73769882 | L22: 0.64560946 | M22: 0.19489353 | N22: 0.6764544 | O22: 0.66974763 | P22: 0.18263436 | Q22: 0.71647656 | R22: 0.64883709 | S22: 0.19498289 | T22: 0.6886484 | U22: 0.65963118 | V22: 0.19999262 | W22: 0.7191249 | X22: 0.65779416 | Y22: 0.19174308 | Z22: 0.6973895 | AA22: 0.67335102 | AB22: 0.17746156 | AC22: 0.72002556 | AD22: 0.66004548 | AE22: 0.19214828 | AF22: 0.72074739 | AG22: 0.6712924 | AH22: 0.18752531 | AI22: 0.73398087 | AJ22: 0.66186323 | AK22: 0.19156008 | AL22: 0.70285923 | AM22: 0.66340799 | AN22: 0.19969769 | AO22: 0.71653094
B23: 10 | I23: 0.67711498 | J23: 0.18377999 | K23: 0.7342369 | L23: 0.671681 | M23: 0.17890427 | N23: 0.71623407 | O23: 0.63161664 | P23: 0.18814916 | Q23: 0.66094064 | R23: 0.66978939 | S23: 0.19274306 | T23: 0.72125531 | U23: 0.66703064 | V23: 0.1903543 | W23: 0.72288079 | X23: 0.66315107 | Y23: 0.19793483 | Z23: 0.70753778 | AA23: 0.66033452 | AB23: 0.1836584 | AC23: 0.70468034 | AD23: 0.67799495 | AE23: 0.19840557 | AF23: 0.73789564 | AG23: 0.67287571 | AH23: 0.18783815 | AI23: 0.7409822 | AJ23: 0.67703148 | AK23: 0.18575799 | AL23: 0.72673249 | AM23: 0.67952687 | AN23: 0.20936815 | AO23: 0.74025967
B24: 1 | C24: Env3 (NonIID, LabelSkew-Deadstatus.event) | D24: fedavg | E24: 600 | F24: 20 | G24: 200 | H24: 10
B25: 2
B26: 3
B27: 4
B28: 5
B29: 6
B30: 7
B31: 8
B32: 9
B33: 10
B34: 1 | C34: Env4 (NonIID, SurvivalSkew-Survival.time) | D34: fedavg | E34: 600 | F34: 20 | G34: 200 | H34: 10
B35: 2
B36: 3
B37: 4
B38: 5
B39: 6
B40: 7
B41: 8
...

Sheet FedProx
B2: Round | C2: Environment | E2: Data | G2: Hyper Parameter | I2: Evaluation | L2: Client-1 | O2: Client-2 | R2: Client-3 | U2: Client-4 | X2: Client-5 | AA2: Client-6 | AD2: Client-7 | AG2: Client-8 | AJ2: Client-9 | AM2: Client-10
C3: env | D3: aggregator | E3: test | F3: features | G3: epoch | H3: round | I3: c-index | J3: IBS | K3: mAUC | L3: c-index | M3: IBS | N3: mAUC | O3: c-index | P3: IBS | Q3: mAUC | R3: c-index | S3: IBS | T3: mAUC | U3: c-index | V3: IBS | W3: mAUC | X3: c-index | Y3: IBS | Z3: mAUC | AA3: c-index | AB3: IBS | AC3: mAUC | AD3: c-index | AE3: IBS | AF3: mAUC | AG3: c-index | AH3: IBS | AI3: mAUC | AJ3: c-index | AK3: IBS | AL3: mAUC | AM3: c-index | AN3: IBS | AO3: mAUC
B4: 1 | C4: Env1 (IID) | D4: FedProx (mu 0.01) | E4: 600 | F4: 20 | G4: 200 | H4: 10 | I4: 0.65884435 | J4: 0.2177184 | K4: 0.71488766 | L4: 0.67677455 | M4: 0.18932064 | N4: 0.73219777 | O4: 0.70638204 | P4: 0.17442962 | Q4: 0.76431507 | R4: 0.69925877 | S4: 0.18170801 | T4: 0.76125294 | U4: 0.67818765 | V4: 0.18788519 | W4: 0.73186055 | X4: 0.69181756 | Y4: 0.18321898 | Z4: 0.75487705 | AA4: 0.70964178 | AB4: 0.17272644 | AC4: 0.77973649 | AD4: 0.69903396 | AE4: 0.18285937 | AF4: 0.76856896 | AG4: 0.68881153 | AH4: 0.18140409 | AI4: 0.74102295 | AJ4: 0.67056659 | AK4: 0.18334403 | AL4: 0.7250007 | AM4: 0.69542415 | AN4: 0.17821841 | AO4: 0.75799808
B5: 2 | I5: 0.71667512 | J5: 0.17929477 | K5: 0.78690214 | L5: 0.7090926 | M5: 0.17314102 | N5: 0.76763923 | O5: 0.63614817 | P5: 0.19640641 | Q5: 0.67011613 | R5: 0.70530295 | S5: 0.18117689 | T5: 0.76964017 | U5: 0.6387656 | V5: 0.18842638 | W5: 0.66946323 | X5: 0.68701626 | Y5: 0.17908492 | Z5: 0.73558613 | AA5: 0.6999621 | AB5: 0.17438483 | AC5: 0.76143928 | AD5: 0.6955751 | AE5: 0.18226446 | AF5: 0.76031145 | AG5: 0.69244381 | AH5: 0.17711228 | AI5: 0.75393147 | AJ5: 0.69599581 | AK5: 0.17956367 | AL5: 0.76884368 | AM5: 0.69114313 | AN5: 0.18221366 | AO5: 0.74881991
B6: 3 | I6: 0.7120055 | J6: 0.17140847 | K6: 0.77963087 | L6: 0.67188333 | M6: 0.17830058 | N6: 0.71909628 | O6: 0.67636668 | P6: 0.18773759 | Q6: 0.72595662 | R6: 0.69095043 | S6: 0.17539518 | T6: 0.74296606 | U6: 0.67053768 | V6: 0.18462389 | W6: 0.71786769 | X6: 0.69553977 | Y6: 0.18279352 | Z6: 0.74800225 | AA6: 0.70426882 | AB6: 0.1765547 | AC6: 0.77272229 | AD6: 0.70039567 | AE6: 0.1740464 | AF6: 0.76011393 | AG6: 0.68241086 | AH6: 0.17869408 | AI6: 0.73415269 | AJ6: 0.68436671 | AK6: 0.1794567 | AL6: 0.7409091 | AM6: 0.68472641 | AN6: 0.18166629 | AO6: 0.74514881
B7: 4 | I7: 0.70410824 | J7: 0.17751625 | K7: 0.7696564 | L7: 0.67707965 | M7: 0.1800562 | N7: 0.72271082 | O7: 0.6964101 | P7: 0.17851139 | Q7: 0.74730391 | R7: 0.69317284 | S7: 0.17267385 | T7: 0.74855338 | U7: 0.68380469 | V7: 0.17980938 | W7: 0.73704299 | X7: 0.70095448 | Y7: 0.17549207 | Z7: 0.76027576 | AA7: 0.67494396 | AB7: 0.18073559 | AC7: 0.72951427 | AD7: 0.67758708 | AE7: 0.18004815 | AF7: 0.73531539 | AG7: 0.67267338 | AH7: 0.18069014 | AI7: 0.72012477 | AJ7: 0.67136306 | AK7: 0.18391478 | AL7: 0.72019884 | AM7: 0.66222292 | AN7: 0.18647977 | AO7: 0.72048126
B8: 5 | I8: 0.70242217 | J8: 0.17678802 | K8: 0.76330257 | L8: 0.67998934 | M8: 0.17367311 | N8: 0.72895776 | O8: 0.67730125 | P8: 0.18192729 | Q8: 0.72870654 | R8: 0.70700829 | S8: 0.17187318 | T8: 0.76545507 | U8: 0.68653131 | V8: 0.17583664 | W8: 0.74022872 | X8: 0.68534624 | Y8: 0.17834781 | Z8: 0.73685649 | AA8: 0.69784247 | AB8: 0.17401978 | AC8: 0.75419607 | AD8: 0.69360961 | AE8: 0.17584607 | AF8: 0.75251501 | AG8: 0.66788813 | AH8: 0.18195316 | AI8: 0.7155242 | AJ8: 0.66851118 | AK8: 0.18149189 | AL8: 0.71328886 | AM8: 0.69291913 | AN8: 0.17688099 | AO8: 0.74983792
B9: 6 | I9: 0.69128765 | J9: 0.17835569 | K9: 0.7468718 | L9: 0.67924104 | M9: 0.17983604 | N9: 0.73027341 | O9: 0.66244131 | P9: 0.18655562 | Q9: 0.7020103 | R9: 0.69518971 | S9: 0.17347713 | T9: 0.74920339 | U9: 0.63817788 | V9: 0.18639217 | W9: 0.68136811 | X9: 0.68843577 | Y9: 0.17374752 | Z9: 0.73330143 | AA9: 0.6760937 | AB9: 0.17883959 | AC9: 0.71727559 | AD9: 0.69459878 | AE9: 0.17055828 | AF9: 0.74519937 | AG9: 0.67244857 | AH9: 0.17862587 | AI9: 0.7227044 | AJ9: 0.66659066 | AK9: 0.18312434 | AL9: 0.70877613 | AM9: 0.69613712 | AN9: 0.17051143 | AO9: 0.74842086
B10: 7 | I10: 0.69421339 | J10: 0.17827568 | K10: 0.75049146 | L10: 0.68990025 | M10: 0.17310169 | N10: 0.74012271 | O10: 0.68293756 | P10: 0.17868442 | Q10: 0.73148708 | R10: 0.69292234 | S10: 0.17173771 | T10: 0.74460614 | U10: 0.65075119 | V10: 0.18270592 | W10: 0.68812615 | X10: 0.67975168 | Y10: 0.17477722 | Z10: 0.72459477 | AA10: 0.69014112 | AB10: 0.17383334 | AC10: 0.74191926 | AD10: 0.70478267 | AE10: 0.1695185 | AF10: 0.76861634 | AG10: 0.6586356 | AH10: 0.18374256 | AI10: 0.70307574 | AJ10: 0.67167779 | AK10: 0.18021666 | AL10: 0.72233969 | AM10: 0.69162486 | AN10: 0.17641466 | AO10: 0.75144101
B11: 8 | I11: 0.68961121 | J11: 0.17310828 | K11: 0.74059921 | L11: 0.67553168 | M11: 0.17720195 | N11: 0.72479027 | O11: 0.68619731 | P11: 0.17587047 | Q11: 0.7392853 | R11: 0.6503658 | S11: 0.17882142 | T11: 0.68401638 | U11: 0.66950356 | V11: 0.17679524 | W11: 0.71581297 | X11: 0.69412347 | Y11: 0.16853855 | Z11: 0.747373 | AA11: 0.6435669 | AB11: 0.18809524 | AC11: 0.68080913 | AD11: 0.6902471 | AE11: 0.17703826 | AF11: 0.74539405 | AG11: 0.66120485 | AH11: 0.1731833 | AI11: 0.69694273 | AJ11: 0.67644376 | AK11: 0.17430016 | AL11: 0.72144142 | AM11: 0.6628267 | AN11: 0.18150905 | AO11: 0.70340178
B12: 9 | I12: 0.69310861 | J12: 0.179236 | K12: 0.74325606 | L12: 0.66841483 | M12: 0.18075104 | N12: 0.71103991 | O12: 0.68789302 | P12: 0.1807363 | Q12: 0.73649935 | R12: 0.65843006 | S12: 0.18319453 | T12: 0.69951437 | U12: 0.66111493 | V12: 0.18336811 | W12: 0.70394243 | X12: 0.68294077 | Y12: 0.17402168 | Z12: 0.73089543 | AA12: 0.67247105 | AB12: 0.17576011 | AC12: 0.71648456 | AD12: 0.67855698 | AE12: 0.17607637 | AF12: 0.72558875 | AG12: 0.66950356 | AH12: 0.17728638 | AI12: 0.71419365 | AJ12: 0.65351635 | AK12: 0.18367892 | AL12: 0.69594431 | AM12: 0.6587769 | AN12: 0.18321244 | AO12: 0.6972421
B13: 10 | I13: 0.68726997 | J13: 0.17497604 | K13: 0.73444362 | L13: 0.66909247 | M13: 0.17594121 | N13: 0.71561537 | O13: 0.69990751 | P13: 0.17511926 | Q13: 0.7513571 | R13: 0.66060429 | S13: 0.18300063 | T13: 0.70226945 | U13: 0.64496393 | V13: 0.18425948 | W13: 0.67751598 | X13: 0.68629365 | Y13: 0.1739337 | Z13: 0.73571031 | AA13: 0.68166257 | AB13: 0.17822004 | AC13: 0.72703292 | AD13: 0.65710046 | AE13: 0.17857388 | AF13: 0.69172873 | AG13: 0.65169539 | AH13: 0.17891063 | AI13: 0.68823592 | AJ13: 0.67329 | AK13: 0.17850187 | AL13: 0.72853699 | AM13: 0.69958956 | AN13: 0.17433296 | AO13: 0.75028163
B14: 1 | D14: FedProx (mu 0.1) | E14: 600 | F14: 20 | G14: 200 | H14: 10 | I14: 0.68545543 | J14: 0.21709563 | K14: 0.7382882 | L14: 0.6819484 | M14: 0.18493623 | N14: 0.73834037 | O14: 0.70153899 | P14: 0.18093444 | Q14: 0.76357768 | R14: 0.70584249 | S14: 0.174237 | T14: 0.76653842 | U14: 0.69505482 | V14: 0.18067353 | W14: 0.75321881 | X14: 0.69938723 | Y14: 0.1794495 | Z14: 0.75670831 | AA14: 0.7076217 | AB14: 0.17175038 | AC14: 0.77505914 | AD14: 0.69841091 | AE14: 0.17998869 | AF14: 0.75974401 | AG14: 0.66487247 | AH14: 0.1946582 | AI14: 0.71664641 | AJ14: 0.67471594 | AK14: 0.19020718 | AL14: 0.73228139 | AM14: 0.69889907 | AN14: 0.18123163 | AO14: 0.76646006
B15: 2 | I15: 0.69826961 | J15: 0.18608459 | K15: 0.75828512 | L15: 0.6769255 | M15: 0.18793545 | N15: 0.72977052 | O15: 0.68270633 | P15: 0.18804898 | Q15: 0.73481739 | R15: 0.71016206 | S15: 0.17461369 | T15: 0.77540742 | U15: 0.66667737 | V15: 0.19075921 | W15: 0.71960511 | X15: 0.70913114 | Y15: 0.1793385 | Z15: 0.7712679 | AA15: 0.69955745 | AB15: 0.1713323 | AC15: 0.76200562 | AD15: 0.69762729 | AE15: 0.17864455 | AF15: 0.75426013 | AG15: 0.65519279 | AH15: 0.19754989 | AI15: 0.70290011 | AJ15: 0.69752773 | AK15: 0.17887981 | AL15: 0.75721886 | AM15: 0.6587769 | AN15: 0.19263823 | AO15: 0.71236923
B16: 3 | I16: 0.70189226 | J16: 0.18355356 | K16: 0.76348904 | L16: 0.68018524 | M16: 0.18953312 | N16: 0.73102329 | O16: 0.67655296 | P16: 0.18979817 | Q16: 0.73788347 | R16: 0.70599986 | S16: 0.17636812 | T16: 0.77058872 | U16: 0.67745541 | V16: 0.18548439 | W16: 0.72795148 | X16: 0.70347556 | Y16: 0.18014964 | Z16: 0.76596219 | AA16: 0.69725154 | AB16: 0.17661194 | AC16: 0.76448308 | AD16: 0.70447436 | AE16: 0.17358088 | AF16: 0.7655463 | AG16: 0.65870304 | AH16: 0.192987 | AI16: 0.70586275 | AJ16: 0.70516164 | AK16: 0.17178694 | AL16: 0.77050191 | AM16: 0.67550277 | AN16: 0.18835481 | AO16: 0.73151038
B17: 4 | I17: 0.68445342 | J17: 0.18619887 | K17: 0.7461527 | L17: 0.69593158 | M17: 0.18071444 | N17: 0.76242956 | O17: 0.68202869 | P17: 0.18131078 | Q17: 0.73402311 | R17: 0.68937676 | S17: 0.18512766 | T17: 0.75108878 | U17: 0.67887171 | V17: 0.17911124 | W17: 0.72714278 | X17: 0.71362092 | Y17: 0.17405627 | Z17: 0.77440272 | AA17: 0.69256906 | AB17: 0.18020129 | AC17: 0.75410303 | AD17: 0.70508135 | AE17: 0.17666213 | AF17: 0.76830261 | AG17: 0.67508848 | AH17: 0.18815668 | AI17: 0.72945464 | AJ17: 0.69446068 | AK17: 0.17386266 | AL17: 0.74752816 | AM17: 0.67153969 | AN17: 0.1927876 | AO17: 0.72302413
B18: 5 | I18: 0.67202785 | J18: 0.18415896 | K18: 0.73102353 | L18: 0.69504198 | M18: 0.18173381 | N18: 0.75565058 | O18: 0.68261319 | P18: 0.18106003 | Q18: 0.74187726 | R18: 0.70792359 | S18: 0.17481765 | T18: 0.76875421 | U18: 0.66542807 | V18: 0.18979926 | W18: 0.71401225 | X18: 0.69853938 | Y18: 0.17632962 | Z18: 0.75582077 | AA18: 0.71066627 | AB18: 0.16676658 | AC18: 0.77671905 | AD18: 0.695938 | AE18: 0.17301377 | AF18: 0.75387928 | AG18: 0.66665489 | AH18: 0.18678943 | AI18: 0.71775449 | AJ18: 0.69424551 | AK18: 0.17415056 | AL18: 0.74996341 | AM18: 0.6903852 | AN18: 0.18397709 | AO18: 0.7478406
B19: 6 | I19: 0.6802559 | J19: 0.18289435 | K19: 0.73955965 | L19: 0.67461638 | M19: 0.1920549 | N19: 0.73279817 | O19: 0.69006083 | P19: 0.17777047 | Q19: 0.74502001 | R19: 0.70629532 | S19: 0.17222109 | T19: 0.76485478 | U19: 0.66838593 | V19: 0.18658287 | W19: 0.7155664 | X19: 0.69659638 | Y19: 0.17533413 | Z19: 0.75607477 | AA19: 0.69738 | AB19: 0.17611328 | AC19: 0.75921208 | AD19: 0.69416843 | AE19: 0.17567257 | AF19: 0.7506036 | AG19: 0.69072883 | AH19: 0.18199749 | AI19: 0.74058827 | AJ19: 0.69459557 | AK19: 0.17220327 | AL19: 0.74616295 | AM19: 0.69089584 | AN19: 0.18559689 | AO19: 0.75032834
B20: 7 | I20: 0.69222222 | J20: 0.17843378 | K20: 0.75533629 | L20: 0.67168421 | M20: 0.19115645 | N20: 0.72659103 | O20: 0.70146833 | P20: 0.17197841 | Q20: 0.76239516 | R20: 0.69940329 | S20: 0.18037281 | T20: 0.76225985 | U20: 0.67064366 | V20: 0.17989925 | W20: 0.7143944 | X20: 0.69574531 | Y20: 0.18023281 | Z20: 0.75085179 | AA20: 0.69763693 | AB20: 0.17252922 | AC20: 0.75900127 | AD20: 0.69630412 | AE20: 0.17140641 | AF20: 0.75228017 | AG20: 0.65476565 | AH20: 0.18584303 | AI20: 0.7012613 | AJ20: 0.6982953 | AK20: 0.16988964 | AL20: 0.7475226 | AM20: 0.6779243 | AN20: 0.18485956 | AO20: 0.73414875
B21: 8 | I21: 0.68703874 | J21: 0.18037392 | K21: 0.74884403 | L21: 0.66863643 | M21: 0.19001358 | N21: 0.71400273 | O21: 0.69633945 | P21: 0.17859982 | Q21: 0.75757139 | R21: 0.70747076 | S21: 0.17472323 | T21: 0.76878131 | U21: 0.66899292 | V21: 0.18118071 | W21: 0.71531602 | X21: 0.70374212 | Y21: 0.17745756 | Z21: 0.76421206 | AA21: 0.69850084 | AB21: 0.16915399 | AC21: 0.75933343 | AD21: 0.68535909 | AE21: 0.17508891 | AF21: 0.73926464 | AG21: 0.6612177 | AH21: 0.18312885 | AI21: 0.70601021 | AJ21: 0.70542178 | AK21: 0.17071051 | AL21: 0.76402171 | AM21: 0.66793952 | AN21: 0.19129396 | AO21: 0.72996873
B22: 9 | I22: 0.68224707 | J22: 0.17999166 | K22: 0.73953413 | L22: 0.66733253 | M22: 0.18183801 | N22: 0.71273112 | O22: 0.67852165 | P22: 0.18096334 | Q22: 0.7350425 | R22: 0.68801827 | S22: 0.18379957 | T22: 0.73772828 | U22: 0.67322256 | V22: 0.17477502 | W22: 0.72065652 | X22: 0.6748733 | Y22: 0.17932346 | Z22: 0.72967089 | AA22: 0.69335911 | AB22: 0.17234966 | AC22: 0.74416755 | AD22: 0.71172288 | AE22: 0.1762338 | AF22: 0.78264833 | AG22: 0.68724428 | AH22: 0.17680278 | AI22: 0.74181989 | AJ22: 0.70040209 | AK22: 0.16884771 | AL22: 0.76122959 | AM22: 0.66748348 | AN22: 0.19293043 | AO22: 0.72612391
B23: 10 | I23: 0.68354455 | J23: 0.17845337 | K23: 0.74535301 | L23: 0.67323219 | M23: 0.18309713 | N23: 0.72210471 | O23: 0.68789302 | P23: 0.17916049 | Q23: 0.74165222 | R23: 0.66652 | S23: 0.18465545 | T23: 0.71637036 | U23: 0.67638917 | V23: 0.17601735 | W23: 0.72483797 | X23: 0.67694477 | Y23: 0.17988075 | Z23: 0.73488525 | AA23: 0.67730125 | AB23: 0.17589616 | AC23: 0.7266434 | AD23: 0.67050878 | AE23: 0.18096134 | AF23: 0.72352417 | AG23: 0.68216357 | AH23: 0.18181656 | AI23: 0.73578973 | AJ23: 0.71269277 | AK23: 0.16625579 | AL23: 0.77590617 | AM23: 0.67003989 | AN23: 0.18024991 | AO23: 0.7207008
B24: 1 | D24: FedProx (mu 1.0) | E24: 600 | F24: 20 | G24: 200 | H24: 10 | I24: 0.69417164 | J24: 0.21846195 | K24: 0.75801445 | L24: 0.7075093 | M24: 0.17667262 | N24: 0.77049694 | O24: 0.70513273 | P24: 0.17941139 | Q24: 0.7676915 | R24: 0.70836679 | S24: 0.17256387 | T24: 0.77135328 | U24: 0.69971802 | V24: 0.18001467 | W24: 0.75860129 | X24: 0.70763776 | Y24: 0.17636156 | Z24: 0.77021002 | AA24: 0.72483573 | AB24: 0.1668235 | AC24: 0.79931004 | AD24: 0.67874004 | AE24: 0.18925403 | AF24: 0.73773495 | AG24: 0.68567061 | AH24: 0.18611411 | AI24: 0.73922937 | AJ24: 0.70211065 | AK24: 0.17495465 | AL24: 0.76425162 | AM24: 0.69652893 | AN24: 0.18222648 | AO24: 0.75717542
B25: 2 | I25: 0.7216081 | J25: 0.18489713 | K25: 0.78508405 | L25: 0.6987128 | M25: 0.18244576 | N25: 0.75594924 | O25: 0.70658115 | P25: 0.17488225 | Q25: 0.76871837 | R25: 0.69380231 | S25: 0.18419488 | T25: 0.75146297 | U25: 0.68864774 | V25: 0.17902077 | W25: 0.74399255 | X25: 0.70453217 | Y25: 0.17748315 | Z25: 0.76560326 | AA25: 0.70711427 | AB25: 0.17813634 | AC25: 0.78024991 | AD25: 0.70290069 | AE25: 0.1784294 | AF25: 0.75994237 | AG25: 0.69849442 | AH25: 0.17913832 | AI25: 0.75743696 | AJ25: 0.6950484 | AK25: 0.17810461 | AL25: 0.75650914 | AM25: 0.71099706 | AN25: 0.17313934 | AO25: 0.77894094
B26: 3 | I26: 0.71536801 | J26: 0.18348333 | K26: 0.77712939 | L26: 0.69602472 | M26: 0.18136255 | N26: 0.74914302 | O26: 0.68488056 | P26: 0.1885573 | Q26: 0.74295054 | R26: 0.70280113 | S26: 0.17868501 | T26: 0.75927525 | U26: 0.70531258 | V26: 0.18008927 | W26: 0.76878525 | X26: 0.70099302 | Y26: 0.17881297 | Z26: 0.76087225 | AA26: 0.70637882 | AB26: 0.17803294 | AC26: 0.77892157 | AD26: 0.70043099 | AE26: 0.17993177 | AF26: 0.76934263 | AG26: 0.69368669 | AH26: 0.18039978 | AI26: 0.75178651 | AJ26: 0.71076262 | AK26: 0.16811069 | AL26: 0.77227471 | AM26: 0.71390675 | AN26: 0.17917618 | AO26: 0.78186266
B27: 4 | I27: 0.70466384 | J27: 0.18417595 | K27: 0.76243979 | L27: 0.7028204 | M27: 0.17775547 | N27: 0.76462041 | O27: 0.68238517 | P27: 0.19329091 | Q27: 0.7379906 | R27: 0.69258512 | S27: 0.18342933 | T27: 0.74809905 | U27: 0.6843924 | V27: 0.18515004 | W27: 0.74286751 | X27: 0.71787625 | Y27: 0.17320798 | Z27: 0.78625702 | AA27: 0.69881236 | AB27: 0.17599139 | AC27: 0.76290359 | AD27: 0.70661006 | AE27: 0.18224343 | AF27: 0.76903663 | AG27: 0.69803195 | AH27: 0.1822037 | AI27: 0.75787085 | AJ27: 0.71085576 | AK27: 0.17284756 | AL27: 0.77629072 | AM27: 0.6981283 | AN27: 0.17713992 | AO27: 0.7592592
B28: 5 | I28: 0.70532222 | J28: 0.17830077 | K28: 0.76719122 | L28: 0.69153815 | M28: 0.18511525 | N28: 0.74902448 | O28: 0.6832266 | P28: 0.18593866 | Q28: 0.73884275 | R28: 0.6956329 | S28: 0.18227731 | T28: 0.75228734 | U28: 0.6881949 | V28: 0.18102917 | W28: 0.74748642 | X28: 0.72198385 | Y28: 0.17315393 | Z28: 0.78809696 | AA28: 0.71322268 | AB28: 0.16952128 | AC28: 0.78201031 | AD28: 0.70859481 | AE28: 0.1768582 | AF28: 0.77379537 | AG28: 0.69699461 | AH28: 0.17788009 | AI28: 0.75655421 | AJ28: 0.7137815 | AK28: 0.16621462 | AL28: 0.77312063 | AM28: 0.70547637 | AN28: 0.178078 | AO28: 0.76802336
B29: 6 | I29: 0.70688946 | J29: 0.17362896 | K29: 0.76918064 | L29: 0.70074573 | M29: 0.18143379 | N29: 0.76448543 | O29: 0.69115597 | P29: 0.18512999 | Q29: 0.74460088 | R29: 0.69729971 | S29: 0.18275735 | T29: 0.758845 | U29: 0.70105083 | V29: 0.17579519 | W29: 0.76350188 | X29: 0.71657235 | Y29: 0.17288814 | Z29: 0.77781673 | AA29: 0.70205284 | AB29: 0.17624356 | AC29: 0.76124728 | AD29: 0.69989787 | AE29: 0.18200475 | AF29: 0.75958361 | AG29: 0.6955494 | AH29: 0.18156348 | AI29: 0.75304958 | AJ29: 0.71028088 | AK29: 0.17543129 | AL29: 0.77826281 | AM29: 0.70249282 | AN29: 0.17714408 | AO29: 0.76285174
B30: 7 | I30: 0.69825676 | J30: 0.17861598 | K30: 0.75702724 | L30: 0.6871126 | M30: 0.18733623 | N30: 0.74514385 | O30: 0.68479706 | P30: 0.1876726 | Q30: 0.73859669 | R30: 0.7011279 | S30: 0.17819796 | T30: 0.75812789 | U30: 0.70380957 | V30: 0.17535119 | W30: 0.76441367 | X30: 0.71115764 | Y30: 0.17984895 | Z30: 0.7741684 | AA30: 0.70014837 | AB30: 0.1795174 | AC30: 0.76632867 | AD30: 0.69597975 | AE30: 0.18138283 | AF30: 0.75285231 | AG30: 0.68243656 | AH30: 0.18486092 | AI30: 0.73977263 | AJ30: 0.72234997 | AK30: 0.16830925 | AL30: 0.79215623 | AM30: 0.69631055 | AN30: 0.1859457 | AO30: 0.75821522
B31: 8 | I31: 0.70542499 | J31: 0.17677415 | K31: 0.76931453 | L31: 0.71205367 | M31: 0.17629193 | N31: 0.77761762 | O31: 0.70085171 | P31: 0.1813837 | Q31: 0.76347121 | R31: 0.69653857 | S31: 0.18821503 | T31: 0.75497515 | U31: 0.69929088 | V31: 0.17672102 | W31: 0.76278676 | X31: 0.70405686 | Y31: 0.18204466 | Z31: 0.76560613 | AA31: 0.69429368 | AB31: 0.18230601 | AC31: 0.7582206 | AD31: 0.69835311 | AE31: 0.18191508 | AF31: 0.75699264 | AG31: 0.68582155 | AH31: 0.18560602 | AI31: 0.73715302 | AJ31: 0.72641903 | AK31: 0.16413773 | AL31: 0.79651226 | AM31: 0.70276902 | AN31: 0.18265297 | AO31: 0.76373189
B32: 9 | I32: 0.70245107 | J32: 0.1771531 | K32: 0.76473171 | L32: 0.70924033 | M32: 0.17595693 | N32: 0.77202205 | O32: 0.68988419 | P32: 0.17934055 | Q32: 0.74466391 | R32: 0.69584166 | S32: 0.18384221 | T32: 0.7549794 | U32: 0.67973883 | V32: 0.1921198 | W32: 0.73528013 | X32: 0.70892881 | Y32: 0.17970142 | Z32: 0.76884519 | AA32: 0.7036522 | AB32: 0.18047824 | AC32: 0.76853366 | AD32: 0.71652097 | AE32: 0.17230208 | AF32: 0.78246045 | AG32: 0.69928125 | AH32: 0.18046954 | AI32: 0.7521123 | AJ32: 0.71461008 | AK32: 0.16674899 | AL32: 0.77667663 | AM32: 0.69261724 | AN32: 0.18102225 | AO32: 0.75362968
B33: 10 | I33: 0.69979189 | J33: 0.1801691 | K33: 0.76092486 | L33: 0.70716566 | M33: 0.17428731 | N33: 0.77259993 | O33: 0.69158311 | P33: 0.18208466 | Q33: 0.74817591 | R33: 0.70187941 | S33: 0.1805699 | T33: 0.7667997 | U33: 0.68319127 | V33: 0.1821507 | W33: 0.73551425 | X33: 0.70377424 | Y33: 0.18390145 | Z33: 0.76494075 | AA33: 0.70203357 | AB33: 0.18184407 | AC33: 0.76840856 | AD33: 0.69662849 | AE33: 0.18046889 | AF33: 0.75662101 | AG33: 0.69030491 | AH33: 0.18261995 | AI33: 0.73887617 | AJ33: 0.70063975 | AK33: 0.17366218 | AL33: 0.75977327 | AM33: 0.69647755 | AN33: 0.18582924 | AO33: 0.7536005
B36: Round | C36: Environment | E36: Data | G36: Hyper Parameter | I36: Evaluation | L36: Client-1 | O36: Client-2 | R36: Client-3 | U36: Client-4 | X36: Client-5 | AA36: Client-6 | AD36: Client-7 | AG36: Client-8 | AJ36: Client-9 | AM36: Client-10
C37: env | D37: aggregator | E37: test | F37: features | G37: epoch | H37: round | I37: c-index | J37: IBS | K37: mAUC | L37: c-index | M37: IBS | N37: mAUC | O37: c-index | P37: IBS | Q37: mAUC | R37: c-index | S37: IBS | T37: mAUC | U37: c-index | V37: IBS | W37: mAUC | X37: c-index | Y37: IBS | Z37: mAUC | AA37: c-index | AB37: IBS | AC37: mAUC | AD37: c-index | AE37: IBS | AF37: mAUC | AG37: c-index | AH37: IBS | AI37: mAUC | AJ37: c-index | AK37: IBS | AL37: mAUC | AM37: c-index | AN37: IBS | AO37: mAUC
B38: 1 | C38: Env2 (NonIID, FeatureSkew-Overall.stage) | D38: FedProx (mu 0.01) | E38: 600 | F38: 20 | G38: 200 | H38: 10 | I38: 0.66404067 | J38: 0.21909012 | K38: 0.72800707 | L38: 0.69303795 | M38: 0.18326029 | N38: 0.74960758 | O38: 0.68376615 | P38: 0.19110522 | Q38: 0.74509341 | R38: 0.66411133 | S38: 0.20200779 | T38: 0.72659153 | U38: 0.64766165 | V38: 0.2206621 | W38: 0.7009194 | X38: 0.64935736 | Y38: 0.19252355 | Z38: 0.68163181 | AA38: 0.66919524 | AB38: 0.18820132 | AC38: 0.72546383 | AD38: 0.60718621 | AE38: 0.23723237 | AF38: 0.65404391 | AG38: 0.69126196 | AH38: 0.19674391 | AI38: 0.76297652 | AJ38: 0.68752369 | AK38: 0.1859559 | AL38: 0.74173223 | AM38: 0.64592419 | AN38: 0.21585684 | AO38: 0.68813756
B39: 2 | I39: 0.70435553 | J39: 0.18539444 | K39: 0.77537712 | L39: 0.72292163 | M39: 0.17035465 | N39: 0.78524077 | O39: 0.71305568 | P39: 0.18735999 | Q39: 0.78557298 | R39: 0.65138387 | S39: 0.19827069 | T39: 0.70045935 | U39: 0.65445413 | V39: 0.20210434 | W39: 0.71230713 | X39: 0.71588187 | Y39: 0.1781813 | Z39: 0.77652512 | AA39: 0.68557747 | AB39: 0.18296471 | AC39: 0.73897059 | AD39: 0.6760102 | AE39: 0.20061945 | AF39: 0.74358212 | AG39: 0.66960954 | AH39: 0.19774944 | AI39: 0.73512693 | AJ39: 0.67125065 | AK39: 0.18935552 | AL39: 0.71488134 | AM39: 0.61853591 | AN39: 0.2366227 | AO39: 0.66706164
B40: 3 | I40: 0.70402474 | J40: 0.18255706 | K40: 0.76955397 | L40: 0.68637394 | M40: 0.18305211 | N40: 0.73729375 | O40: 0.67705717 | P40: 0.18547393 | Q40: 0.73371284 | R40: 0.67413464 | S40: 0.19416311 | T40: 0.73050042 | U40: 0.65736702 | V40: 0.19948389 | W40: 0.72446204 | X40: 0.69474009 | Y40: 0.18289531 | Z40: 0.75106331 | AA40: 0.66847264 | AB40: 0.18413847 | AC40: 0.72466107 | AD40: 0.64688767 | AE40: 0.21159169 | AF40: 0.70581951 | AG40: 0.67933739 | AH40: 0.19847689 | AI40: 0.75152722 | AJ40: 0.66132047 | AK40: 0.1910264 | AL40: 0.69744896 | AM40: 0.6405127 | AN40: 0.21652989 | AO40: 0.68688471
B41: 4 | I41: 0.6957421 | J41: 0.18357376 | K41: 0.76326599 | L41: 0.67964891 | M41: 0.17753299 | N41: 0.72440824 | O41: 0.67537431 | P41: 0.17955926 | Q41: 0.72778562 | R41: 0.61639058 | S41: 0.20829122 | T41: 0.66067986 | U41: 0.64196754 | V41: 0.20664548 | W41: 0.69705307 | X41: 0.67443332 | Y41: 0.18686255 | Z41: 0.72403179 | AA41: 0.69443499 | AB41: 0.17363118 | AC41: 0.75051906 | AD41: 0.66346901 | AE41: 0.19591203 | AF41: 0.73016548 | AG41: 0.66353645 | AH41: 0.20440758 | AI41: 0.72803445 | AJ41: 0.67872719 | AK41: 0.17936859 | AL41: 0.71866005 | AM41: 0.63401247 | AN41: 0.21536088 | AO41: 0.68318244
B42: 5 | I42: 0.69301547 | J42: 0.17921389 | K42: 0.75773609 | L42: 0.69794524 | M42: 0.17522496 | N42: 0.7474842 | O42: 0.67750037 | P42: 0.18291098 | Q42: 0.72696464 | R42: 0.63806227 | S42: 0.19611117 | T42: 0.67937796 | U42: 0.65732527 | V42: 0.19694501 | W42: 0.70844063 | X42: 0.65025339 | Y42: 0.18957503 | Z42: 0.68778092 | AA42: 0.66376769 | AB42: 0.18100192 | AC42: 0.72129574 | AD42: 0.66785923 | AE42: 0.1992134 | AF42: 0.72744495 | AG42: 0.66443569 | AH42: 0.21579901 | AI42: 0.72636612 | AJ42: 0.67455536 | AK42: 0.18579439 | AL42: 0.7170067 | AM42: 0.67046382 | AN42: 0.20677812 | AO42: 0.73786403
B43: 6 | I43: 0.68811783 | J43: 0.18173824 | K43: 0.75183589 | L43: 0.67910616 | M43: 0.1746076 | N43: 0.72418394 | O43: 0.69533744 | P43: 0.17839177 | Q43: 0.75363979 | R43: 0.66564967 | S43: 0.19477732 | T43: 0.71612628 | U43: 0.63764155 | V43: 0.20994887 | W43: 0.69250355 | X43: 0.64707073 | Y43: 0.19212731 | Z43: 0.67929705 | AA43: 0.65905952 | AB43: 0.19080181 | AC43: 0.72071055 | AD43: 0.65629115 | AE43: 0.19187213 | AF43: 0.70624364 | AG43: 0.67865975 | AH43: 0.19891149 | AI43: 0.74044237 | AJ43: 0.64794748 | AK43: 0.19047993 | AL43: 0.68020706 | AM43: 0.67091022 | AN43: 0.20742089 | AO43: 0.72647687
...

Sheet Stacking_Output
B2: Round | C2: Environment | E2: Public Data | G2: Test Data | I2: Hyper Parameter | K2: Evaluation(Global) | O2: Evaluation(META) | U2: Client-1 | X2: Client-2 | AA2: Client-3 | AD2: Client-4 | AG2: Client-5 | AJ2: Client-6 | AM2: Client-7 | AP2: Client-8 | AS2: Client-9 | AV2: Client-10
C3: env | D3: aggregator | E3: Public | F3: Features | G3: Test | H3: Features | I3: epoch | J3: round | K3: Model | L3: c-index | M3: IBS | N3: mAUC | O3: Shape | P3: Input | Q3: Model | R3: c-index | S3: IBS | T3: mAUC | U3: c-index | V3: IBS | W3: mAUC | X3: c-index | Y3: IBS | Z3: mAUC | AA3: c-index | AB3: IBS | AC3: mAUC | AD3: c-index | AE3: IBS | AF3: mAUC | AG3: c-index | AH3: IBS | AI3: mAUC | AJ3: c-index | AK3: IBS | AL3: mAUC | AM3: c-index | AN3: IBS | AO3: mAUC | AP3: c-index | AQ3: IBS | AR3: mAUC | AS3: c-index | AT3: IBS | AU3: mAUC | AV3: c-index | AW3: IBS | AX3: mAUC
B4: 1 | C4: Env1 (IID) | D4: fedavg | E4: 504 | F4: 20 | G4: 600 | H4: 20 | I4: 200 | J4: 10 | K4: Deepsurvk (DNN Layer5) | L4: 0.66817396 | M4: 0.219625 | N4: 0.72101811 | O4: 504x10 | P4: Input: 504x20 Model: Each Client Model Output: Deepsurvk → 상대적 위험도: Risk Score | Q4: Deepsurvk (DNN Layer5) | R4: 0.71986421 | S4: 0.22053378 | T4: 0.7902151 | U4: 0.68217321 | V4: 0.19149304 | W4: 0.73309077 | X4: 0.69569714 | Y4: 0.17934428 | Z4: 0.75246786 | AA4: 0.70592278 | AB4: 0.17556145 | AC4: 0.77041672 | AD4: 0.68482275 | AE4: 0.18513615 | AF4: 0.73919564 | AG4: 0.68924509 | AH4: 0.181042 | AI4: 0.75156553 | AJ4: 0.70072646 | AK4: 0.17863127 | AL4: 0.7636965 | AM4: 0.68964653 | AN4: 0.1822033 | AO4: 0.75212293 | AP4: 0.6735405 | AQ4: 0.18928715 | AR4: 0.72687548 | AS4: 0.68275771 | AT4: 0.18346393 | AU4: 0.74396157 | AV4: 0.69646149 | AW4: 0.18525 | AX4: 0.75724419
B5: 2 | L5: 0.71329334 | M5: 0.18902254 | N5: 0.78050855 | R5: 0.71130859 | S5: 0.22061793 | T5: 0.77940678 | U5: 0.69313751 | V5: 0.1833608 | W5: 0.75530417 | X5: 0.69113992 | Y5: 0.18776352 | Z5: 0.74998375 | AA5: 0.70518733 | AB5: 0.17906806 | AC5: 0.76677114 | AD5: 0.69577421 | AE5: 0.17799437 | AF5: 0.76235235 | AG5: 0.71361128 | AH5: 0.18162079 | AI5: 0.77521301 | AJ5: 0.71320663 | AK5: 0.16921074 | AL5: 0.78146405 | AM5: 0.69506767 | AN5: 0.18019948 | AO5: 0.7562131 | AP5: 0.68303712 | AQ5: 0.18226958 | AR5: 0.74269191 | AS5: 0.70804884 | AT5: 0.17227955 | AU5: 0.77825713 | AV5: 0.70674173 | AW5: 0.18132184 | AX5: 0.76519499
B6: 3 | L6: 0.70676742 | M6: 0.18290203 | N6: 0.77777702 | R6: 0.71970042 | S6: 0.22021503 | T6: 0.79119773 | U6: 0.70875539 | V6: 0.17784811 | W6: 0.77416088 | X6: 0.70305164 | Y6: 0.17758496 | Z6: 0.7589367 | AA6: 0.71062131 | AB6: 0.16854569 | AC6: 0.77633248 | AD6: 0.7029874 | AE6: 0.17585613 | AF6: 0.76378307 | AG6: 0.7229955 | AH6: 0.16954301 | AI6: 0.78799062 | AJ6: 0.68859956 | AK6: 0.1749847 | AL6: 0.75323151 | AM6: 0.70248961 | AN6: 0.17645111 | AO6: 0.7639592 | AP6: 0.69279066 | AQ6: 0.18526892 | AR6: 0.75456798 | AS6: 0.7056241 | AT6: 0.1767397 | AU6: 0.77200404 | AV6: 0.71795333 | AW6: 0.17361696 | AX6: 0.7844597
B7: 4 | L7: 0.70884531 | M7: 0.17829245 | N7: 0.77545845 | R7: 0.73322435 | S7: 0.22023213 | T7: 0.80789024 | U7: 0.71058598 | V7: 0.17248336 | W7: 0.78121348 | X7: 0.71023271 | Y7: 0.176888 | Z7: 0.77559972 | AA7: 0.71826485 | AB7: 0.17366361 | AC7: 0.78669509 | AD7: 0.71661089 | AE7: 0.17343221 | AF7: 0.78650143 | AG7: 0.71350209 | AH7: 0.17147256 | AI7: 0.77445048 | AJ7: 0.71635397 | AK7: 0.17386615 | AL7: 0.78389799 | AM7: 0.70862371 | AN7: 0.1753356 | AO7: 0.771995 | AP7: 0.71852178 | AQ7: 0.17400141 | AR7: 0.78354421 | AS7: 0.71581763 | AT7: 0.17285387 | AU7: 0.78423449 | AV7: 0.70685093 | AW7: 0.17568454 | AX7: 0.77563753
B8: 5 | L8: 0.70194364 | M8: 0.17781747 | N8: 0.76076739 | R8: 0.72989074 | S8: 0.22038085 | T8: 0.80432081 | U8: 0.69720336 | V8: 0.18282893 | W8: 0.75914178 | X8: 0.70124673 | Y8: 0.17787808 | Z8: 0.76458371 | AA8: 0.72104286 | AB8: 0.1689977 | AC8: 0.7905408 | AD8: 0.67839961 | AE8: 0.18229309 | AF8: 0.72574185 | AG8: 0.72316892 | AH8: 0.17125657 | AI8: 0.78738182 | AJ8: 0.70471202 | AK8: 0.16995254 | AL8: 0.7748908 | AM8: 0.71119618 | AN8: 0.17643885 | AO8: 0.78102297 | AP8: 0.70842138 | AQ8: 0.17910669 | AR8: 0.77337614 | AS8: 0.70813877 | AT8: 0.17130747 | AU8: 0.77813707 | AV8: 0.71522028 | AW8: 0.17638465 | AX8: 0.77603524
B9: 6 | L9: 0.6911078 | M9: 0.18244611 | N9: 0.74476803 | R9: 0.73394696 | S9: 0.2204178 | T9: 0.8085713 | U9: 0.66333734 | V9: 0.19744734 | W9: 0.71580771 | X9: 0.71047679 | Y9: 0.18506722 | Z9: 0.77500769 | AA9: 0.70637882 | AB9: 0.17560282 | AC9: 0.77167118 | AD9: 0.67387451 | AE9: 0.1758579 | AF9: 0.72534557 | AG9: 0.72962097 | AH9: 0.16895726 | AI9: 0.79234451 | AJ9: 0.71044467 | AK9: 0.17272964 | AL9: 0.76604596 | AM9: 0.7124776 | AN9: 0.17414234 | AO9: 0.7787007 | AP9: 0.71820704 | AQ9: 0.18617308 | AR9: 0.78609443 | AS9: 0.71264781 | AT9: 0.17096949 | AU9: 0.78592854 | AV9: 0.70827044 | AW9: 0.17480694 | AX9: 0.77081225
B10: 7 | L10: 0.70513595 | M10: 0.18018842 | N10: 0.76410102 | R10: 0.70721383 | S10: 0.22026421 | T10: 0.77847608 | U10: 0.70882283 | V10: 0.18038885 | W10: 0.76914749 | X10: 0.71820383 | Y10: 0.1767057 | Z10: 0.78482025 | AA10: 0.70599665 | AB10: 0.17636833 | AC10: 0.76905397 | AD10: 0.67574685 | AE10: 0.18151159 | AF10: 0.72288766 | AG10: 0.72277069 | AH10: 0.16763966 | AI10: 0.78782555 | AJ10: 0.69530854 | AK10: 0.17777633 | AL10: 0.76867407 | AM10: 0.70601592 | AN10: 0.1765624 | AO10: 0.77729905 | AP10: 0.70579753 | AQ10: 0.1769469 | AR10: 0.76688505 | AS10: 0.71226564 | AT10: 0.17424806 | AU10: 0.77772606 | AV10: 0.70362329 | AW10: 0.17832547 | AX10: 0.76428842
B11: 8 | L11: 0.68893357 | M11: 0.18349799 | N11: 0.74178023 | R11: 0.7268269 | S11: 0.22024039 | T11: 0.80046479 | U11: 0.70447115 | V11: 0.17722897 | W11: 0.76956918 | X11: 0.70713354 | Y11: 0.18499333 | Z11: 0.76555912 | AA11: 0.72421911 | AB11: 0.16980475 | AC11: 0.7911788 | AD11: 0.65739914 | AE11: 0.18256291 | AF11: 0.70367021 | AG11: 0.72326206 | AH11: 0.1715765 | AI11: 0.79186583 | AJ11: 0.68281552 | AK11: 0.18015955 | AL11: 0.73110417 | AM11: 0.67624786 | AN11: 0.18280101 | AO11: 0.73756326 | AP11: 0.65535016 | AQ11: 0.18909776 | AR11: 0.71464954 | AS11: 0.70098659 | AT11: 0.17793021 | AU11: 0.76437784 | AV11: 0.6932724 | AW11: 0.17963983 | AX11: 0.74822439
B12: 9 | L12: 0.68890145 | M12: 0.18228729 | N12: 0.74835039 | R12: 0.70772447 | S12: 0.22037684 | T12: 0.77631846 | U12: 0.68867343 | V12: 0.17887376 | W12: 0.74127439 | X12: 0.67327715 | Y12: 0.18333505 | Z12: 0.71710315 | AA12: 0.70637882 | AB12: 0.17390899 | AC12: 0.76575927 | AD12: 0.66445496 | AE12: 0.18351989 | AF12: 0.70557653 | AG12: 0.68082435 | AH12: 0.17814139 | AI12: 0.72482817 | AJ12: 0.68756222 | AK12: 0.1784469 | AL12: 0.74375768 | AM12: 0.67779262 | AN12: 0.1861874 | AO12: 0.73172234 | AP12: 0.7021813 | AQ12: 0.17623185 | AR12: 0.76106991 | AS12: 0.68770353 | AT12: 0.1754069 | AU12: 0.74060579 | AV12: 0.68711582 | AW12: 0.17950031 | AX12: 0.74697451
B13: 10 | L13: 0.6997405 | M13: 0.17897042 | N13: 0.75507877 | R13: 0.71959123 | S13: 0.22006445 | T13: 0.78663015 | U13: 0.66476649 | V13: 0.18226448 | W13: 0.71015608 | X13: 0.6880825 | Y13: 0.18160566 | Z13: 0.7345747 | AA13: 0.69766583 | AB13: 0.17618555 | AC13: 0.74916845 | AD13: 0.67490221 | AE13: 0.18006669 | AF13: 0.71950704 | AG13: 0.6974346 | AH13: 0.17552861 | AI13: 0.74599127 | AJ13: 0.70082602 | AK13: 0.17187975 | AL13: 0.76049331 | AM13: 0.69816041 | AN13: 0.17728703 | AO13: 0.75213894 | AP13: 0.67833217 | AQ13: 0.17903443 | AR13: 0.72258528 | AS13: 0.68141206 | AT13: 0.17864888 | AU13: 0.72526333 | AV13: 0.68533982 | AW13: 0.17576363 | AX13: 0.7333942
B14: 1 | C14: Env2 (NonIID, FeatureSkew-Overall.stage) | D14: fedavg | E14: 504 | F14: 20 | G14: 600 | H14: 20 | I14: 200 | J14: 10 | K14: Deepsurvk (DNN Layer5) | L14: 0.65431603 | M14: 0.22052151 | N14: 0.70714275 | O14: 504x10 | P14: Input: 504x20 Model: Each Client Model Output: Deepsurvk → 상대적 위험도: Risk Score | Q14: Deepsurvk (DNN Layer5) | R14: 0.73213884 | S14: 0.22076165 | T14: 0.80122145 | U14: 0.69392756 | V14: 0.17736549 | W14: 0.75105907 | X14: 0.69429689 | Y14: 0.19216723 | Z14: 0.76308512 | AA14: 0.64040671 | AB14: 0.2134109 | AC14: 0.70037233 | AD14: 0.64530115 | AE14: 0.22173347 | AF14: 0.69869145 | AG14: 0.6941042 | AH14: 0.18525091 | AI14: 0.74581518 | AJ14: 0.67000456 | AK14: 0.19405152 | AL14: 0.72613175 | AM14: 0.69431937 | AN14: 0.19397772 | AO14: 0.7752071 | AP14: 0.65777489 | AQ14: 0.21378914 | AR14: 0.71199374 | AS14: 0.6796168 | AT14: 0.18384883 | AU14: 0.72416847 | AV14: 0.66372915 | AW14: 0.21275149 | AX14: 0.7111328
B15: 2 | L15: 0.68547791 | M15: 0.18938095 | N15: 0.74953681 | R15: 0.73081246 | S15: 0.22082452 | T15: 0.79830787 | U15: 0.71033869 | V15: 0.18296309 | W15: 0.76806902 | X15: 0.73228336 | Y15: 0.17389079 | Z15: 0.79924648 | AA15: 0.66924021 | AB15: 0.19359231 | AC15: 0.72817654 | AD15: 0.64689409 | AE15: 0.20807898 | AF15: 0.70377124 | AG15: 0.71004965 | AH15: 0.18646107 | AI15: 0.7693983 | AJ15: 0.6702936 | AK15: 0.19705637 | AL15: 0.72609431 | AM15: 0.66194994 | AN15: 0.19902864 | AO15: 0.71838913 | AP15: 0.67942089 | AQ15: 0.20516191 | AR15: 0.74381822 | AS15: 0.69978868 | AT15: 0.18082242 | AU15: 0.74962171 | AV15: 0.63329308 | AW15: 0.2191564 | AX15: 0.68155002
B16: 3 | L16: 0.69194281 | M16: 0.18526814 | N16: 0.7610158 | R16: 0.72232428 | S16: 0.22062332 | T16: 0.79038517 | U16: 0.69286453 | V16: 0.18169209 | W16: 0.75431616 | X16: 0.68243334 | Y16: 0.18114842 | Z16: 0.73846602 | AA16: 0.6264428 | AB16: 0.2003803 | AC16: 0.66356211 | AD16: 0.66177009 | AE16: 0.2098102 | AF16: 0.71992696 | AG16: 0.71867593 | AH16: 0.17367675 | AI16: 0.78383149 | AJ16: 0.64216666 | AK16: 0.20271211 | AL16: 0.69150509 | AM16: 0.69210981 | AN16: 0.18711801 | AO16: 0.7574856 | AP16: 0.67569868 | AQ16: 0.20162023 | AR16: 0.74089888 | AS16: 0.69851368 | AT16: 0.18542607 | AU16: 0.75427717 | AV16: 0.61681772 | AW16: 0.2306151 | AX16: 0.66304007
B17: 4 | L17: 0.68207365 | M17: 0.17978915 | N17: 0.74385482 | R17: 0.71959444 | S17: 0.21968515 | T17: 0.78187954 | U17: 0.69103393 | V17: 0.17566421 | W17: 0.7392559 | X17: 0.65966651 | Y17: 0.18368333 | Z17: 0.70249547 | AA17: 0.64097516 | AB17: 0.19935511 | AC17: 0.68339311 | AD17: 0.64335173 | AE17: 0.20494335 | AF17: 0.70459201 | AG17: 0.66118558 | AH17: 0.18651071 | AI17: 0.69562719 | AJ17: 0.67068863 | AK17: 0.18089898 | AL17: 0.72232116 | AM17: 0.66482751 | AN17: 0.1945474 | AO17: 0.72001535 | AP17: 0.6685176 | AQ17: 0.19647421 | AR17: 0.73340639 | AS17: 0.65703302 | AT17: 0.19798837 | AU17: 0.69850504 | AV17: 0.65589291 | AW17: 0.21703638 | AX17: 0.70487524
B18: 5 | L18: 0.68102025 | M18: 0.17863089 | N18: 0.74488834 | R18: 0.7282689 | S18: 0.21986069 | T18: 0.79631195 | U18: 0.67390662 | V18: 0.18113773 | W18: 0.71798891 | X18: 0.65816992 | Y18: 0.18989381 | Z18: 0.70744911 | AA18: 0.65387605 | AB18: 0.19963388 | AC18: 0.69950899 | AD18: 0.64907475 | AE18: 0.20302632 | AF18: 0.71089191 | AG18: 0.64465562 | AH18: 0.19866866 | AI18: 0.67524371 | AJ18: 0.65301535 | AK18: 0.18796951 | AL18: 0.70958242 | AM18: 0.65990417 | AN18: 0.19353052 | AO18: 0.71367414 | AP18: 0.65071907 | AQ18: 0.20946272 | AR18: 0.70859578 | AS18: 0.63891976 | AT18: 0.19542366 | AU18: 0.66825909 | AV18: 0.67902587 | AW18: 0.2000702 | AX18: 0.73811331
B19: 6 | L19: 0.68531091 | M19: 0.17890393 | N19: 0.74402857 | R19: 0.72265507 | S19: 0.2198027 | T19: 0.78469064 | U19: 0.68900743 | V19: 0.17587454 | W19: 0.73547065 | X19: 0.65127146 | Y19: 0.19033646 | Z19: 0.69182603 | AA19: 0.64860264 | AB19: 0.19165374 | AC19: 0.68352747 | AD19: 0.64308195 | AE19: 0.20944756 | AF19: 0.69558733 | AG19: 0.64547136 | AH19: 0.1968216 | AI19: 0.67884208 | AJ19: 0.67389699 | AK19: 0.17950386 | AL19: 0.72501089 | AM19: 0.67966176 | AN19: 0.19171527 | AO19: 0.7419023 | AP19: 0.68804396 | AQ19: 0.19449558 | AR19: 0.75549532 | AS19: 0.65110125 | AT19: 0.19017831 | AU19: 0.68882172 | AV19: 0.63331235 | AW19: 0.2204772 | AX19: 0.6674543
B20: 7 | L20: 0.68816921 | M20: 0.17951563 | N20: 0.74887461 | R20: 0.71825843 | S20: 0.21985554 | T20: 0.78600572 | U20: 0.67617399 | V20: 0.17925865 | W20: 0.7225137 | X20: 0.65736381 | Y20: 0.18581696 | Z20: 0.69893109 | AA20: 0.68685247 | AB20: 0.18063303 | AC20: 0.74674728 | AD20: 0.66986967 | AE20: 0.19886079 | AF20: 0.72279006 | AG20: 0.64628389 | AH20: 0.19726081 | AI20: 0.67944798 | AJ20: 0.66871993 | AK20: 0.18470898 | AL20: 0.71361647 | AM20: 0.69123626 | AN20: 0.18843618 | AO20: 0.75436061 | AP20: 0.68907487 | AQ20: 0.18789713 | AR20: 0.75213723 | AS20: 0.65881866 | AT20: 0.18627724 | AU20: 0.7006839 | AV20: 0.68105237 | AW20: 0.1999034 | AX20: 0.73463148
B21: 8 | L21: 0.68172037 | M21: 0.18485503 | N21: 0.73332007 | R21: 0.71024235 | S21: 0.21960727 | T21: 0.77201675 | U21: 0.67652726 | V21: 0.18084257 | W21: 0.72048258 | X21: 0.66964165 | Y21: 0.17887464 | Z21: 0.71643121 | AA21: 0.65176604 | AB21: 0.19626626 | AC21: 0.69718369 | AD21: 0.6510884 | AE21: 0.21132259 | AF21: 0.6912548 | AG21: 0.64641235 | AH21: 0.21251478 | AI21: 0.68066259 | AJ21: 0.67151721 | AK21: 0.18318652 | AL21: 0.72414899 | AM21: 0.66409527 | AN21: 0.18976117 | AO21: 0.71869671 | AP21: 0.68454977 | AQ21: 0.19028002 | AR21: 0.74598336 | AS21: 0.63914135 | AT21: 0.19619453 | AU21: 0.66825848 | AV21: 0.67026791 | AW21: 0.21079391 | AX21: 0.73067992
B22: 9 | L22: 0.67309409 | M22: 0.1874442 | N22: 0.72542232 | R22: 0.69960241 | S22: 0.21973872 | T22: 0.75757385 | U22: 0.64316867 | V22: 0.18796657 | W22: 0.67336792 | X22: 0.6364886 | Y22: 0.18761246 | Z22: 0.66546122 | AA22: 0.64233366 | AB22: 0.20036106 | AC22: 0.6864125 | AD22: 0.651811 | AE22: 0.20758893 | AF22: 0.69146613 | AG22: 0.66324099 | AH22: 0.20149058 | AI22: 0.70334781 | AJ22: 0.64025577 | AK22: 0.18492642 | AL22: 0.67699187 | AM22: 0.66198205 | AN22: 0.19189055 | AO22: 0.71513631 | AP22: 0.67407041 | AQ22: 0.19802997 | AR22: 0.72682024 | AS22: 0.6673229 | AT22: 0.18793322 | AU22: 0.71126114 | AV22: 0.66898007 | AW22: 0.20922335 | AX22: 0.71840265
B23: 10 | L23: 0.68155016 | M23: 0.18192492 | N23: 0.73687783 | R23: 0.72679479 | S23: 0.21992995 | T23: 0.79236432 | U23: 0.65529235 | V23: 0.18420913 | W23: 0.6910092 | X23: 0.65210647 | Y23: 0.18432059 | Z23: 0.69180979 | AA23: 0.65168575 | AB23: 0.19456339 | AC23: 0.69145546 | AD23: 0.68023663 | AE23: 0.19439974 | AF23: 0.74380177 | AG23: 0.64119676 | AH23: 0.19686569 | AI23: 0.67297602 | AJ23: 0.66614746 | AK23: 0.18078312 | AL23: 0.71445122 | AM23: 0.67419887 | AN23: 0.19012977 | AO23: 0.73258092 | AP23: 0.68529807 | AQ23: 0.17390188 | AR23: 0.74285286 | AS23: 0.6514481 | AT23: 0.19832389 | AU23: 0.68596963 | AV23: 0.65384714 | AW23: 0.20685479 | AX23: 0.69328822
B24: 1 | C24: Env3 (NonIID, LabelSkew-Deadstatus.event) | D24: fedavg | E24: 504 | F24: 20 | G24: 600 | H24: 20 | I24: 200 | J24: 10 | K24: Deepsurvk (DNN Layer5) | L24: 0.51243199 | M24: 0.22163515 | N24: 0.52061241 | O24: 504x10 | P24: Input: 504x20 Model: Each Client Model Output: Deepsurvk → 상대적 위험도: Risk Score | Q24: Deepsurvk (DNN Layer5) | R24: 0.5 | S24: 0.22165622 | T24: 0.5 | U24: 0.59788871 | V24: 0.26120434 | W24: 0.6451434 | X24: 0.6846975 | Y24: 0.21731648 | Z24: 0.75290012 | AA24: 0.65992023 | AB24: 0.31413051 | AC24: 0.70416609 | AD24: 0.66887409 | AE24: 0.20600461 | AF24: 0.72155655 | AG24: 0.63916062 | AH24: 0.24126339 | AI24: 0.67573087 | AJ24: 0.68482275 | AK24: 0.27210157 | AL24: 0.73856288 | AM24: 0.51769897 | AN24: 0.34744871 | AO24: 0.51612817 | AP24: 0.47144913 | AQ24: 0.3440632 | AR24: 0.47169246 | AS24: 0.47678676 | AT24: 0.3751409 | AU24: 0.47238303 | AV24: 0.57072845 | AW24: 0.49119871 | AX24: 0.59309385
B25: 2 | L25: 0.49864793 | M25: 0.22163788 | N25: 0.49823456 | R25: 0.5 | S25: 0.22165622 | T25: 0.5 | U25: 0.65429676 | V25: 0.26529814 | W25: 0.71962026 | X25: 0.65442522 | Y25: 0.21681143 | Z25: 0.72345606 | AA25: 0.5 | AB25: 0.33243695 | AC25: 0.5 | AD25: 0.66418198 | AE25: 0.19680339 | AF25: 0.71703432 | AG25: 0.704317 | AH25: 0.22329504 | AI25: 0.76889793 | AJ25: 0.5 | AK25: 0.29180793 | AL25: 0.5 | AM25: 0.5 | AN25: 0.34322011 | AO25: 0.5 | AP25: 0.5 | AQ25: 0.34167703 | AR25: 0.5 | AS25: 0.57097574 | AT25: 0.37050729 | AU25: 0.60814343 | AV25: 0.5 | AW25: 0.49119871 | AX25: 0.5
B26: 3 | L26: 0.5 | M26: 0.22163991 | N26: 0.5 | R26: 0.5 | S26: 0.22165622 | T26: 0.5 | U26: 0.62669972 | V26: 0.26397646 | W26: 0.68025485 | X26: 0.5 | Y26: 0.25091784 | Z26: 0.5 | AA26: 0.5 | AB26: 0.33243695 | AC26: 0.5 | AD26: 0.6546115 | AE26: 0.20146082 | AF26: 0.69965234 | AG26: 0.5 | AH26: 0.25431776 | AI26: 0.5 | AJ26: 0.5 | AK26: 0.29180793 | AL26: 0.5 | AM26: 0.5 | AN26: 0.34322011 | AO26: 0.5 | AP26: 0.5 | AQ26: 0.34167703 | AR26: 0.5 | AS26: 0.5 | AT26: 0.37307327 | AU26: 0.5 | AV26: 0.5 | AW26: 0.49119871 | AX26: 0.5
B27: 4 | L27: 0.5 | M27: 0.22163991 | N27: 0.5 | R27: 0.5 | S27: 0.22165622 | T27: 0.5 | U27: 0.5 | V27: 0.27928233 | W27: 0.5 | X27: 0.5 | Y27: 0.25091784 | Z27: 0.5 | AA27: 0.5 | AB27: 0.33243695 | AC27: 0.5 | AD27: 0.66197242 | AE27: 0.20085503 | AF27: 0.72440674 | AG27: 0.5 | AH27: 0.25431776 | AI27: 0.5 | AJ27: 0.5 | AK27: 0.29180793 | AL27: 0.5 | AM27: 0.5 | AN27: 0.34322011 | AO27: 0.5 | AP27: 0.5 | AQ27: 0.34167703 | AR27: 0.5 | AS27: 0.5 | AT27: 0.37307327 | AU27: 0.5 | AV27: 0.5 | AW27: 0.49119871 | AX27: 0.5
B28: 5 | L28: 0.5 | M28: 0.22163991 | N28: 0.5 | R28: 0.5 | S28: 0.22165622 | T28: 0.5 | U28: 0.5 | V28: 0.27928233 | W28: 0.5 | X28: 0.5 | Y28: 0.25091784 | Z28: 0.5 | AA28: 0.5 | AB28: 0.33243695 | AC28: 0.5 | AD28: 0.5 | AE28: 0.23802117 | AF28: 0.5 | AG28: 0.5 | AH28: 0.25431776 | AI28: 0.5 | AJ28: 0.5 | AK28: 0.29180793 | AL28: 0.5 | AM28: 0.5 | AN28: 0.34322011 | AO28: 0.5 | AP28: 0.5 | AQ28: 0.34167703 | AR28: 0.5 | AS28: 0.5 | AT28: 0.37307327 | AU28: 0.5 | AV28: 0.5 | AW28: 0.49119871 | AX28: 0.5
B29: 6 | L29: 0.5 | M29: 0.22163991 | N29: 0.5 | R29: 0.5 | S29: 0.22165622 | T29: 0.5 | U29: 0.5 | V29: 0.27928233 | W29: 0.5 | X29: 0.5 | Y29: 0.25091784 | Z29: 0.5 | AA29: 0.5 | AB29: 0.33243695 | AC29: 0.5 | AD29: 0.5 | AE29: 0.23802117 | AF29: 0.5 | AG29: 0.5 | AH29: 0.25431776 | AI29: 0.5 | AJ29: 0.5 | AK29: 0.29180793 | AL29: 0.5 | AM29: 0.5 | AN29: 0.34322011 | AO29: 0.5 | AP29: 0.5 | AQ29: 0.34167703 | AR29: 0.5 | AS29: 0.5 | AT29: 0.37307327 | AU29: 0.5 | AV29: 0.5 | AW29: 0.49119871 | AX29: 0.5
B30: 7 | L30: 0.5 | M30: 0.22163991 | N30: 0.5 | R30: 0.5 | S30: 0.22165622 | T30: 0.5 | U30: 0.5 | V30: 0.27928233 | W30: 0.5 | X30: 0.5 | Y30: 0.25091784 | Z30: 0.5 | AA30: 0.5 | AB30: 0.33243695 | AC30: 0.5 | AD30: 0.5 | AE30: 0.23802117 | AF30: 0.5 | AG30: 0.5 | AH30: 0.25431776 | AI30: 0.5 | AJ30: 0.5 | AK30: 0.29180793 | AL30: 0.5 | AM30: 0.5 | AN30: 0.34322011 | AO30: 0.5 | AP30: 0.5 | AQ30: 0.34167703 | AR30: 0.5 | AS30: 0.5 | AT30: 0.37307327 | AU30: 0.5 | AV30: 0.5 | AW30: 0.49119871 | AX30: 0.5
B31: 8 | L31: 0.5 | M31: 0.22163991 | N31: 0.5 | R31: 0.5 | S31: 0.22165622 | T31: 0.5 | U31: 0.5 | V31: 0.27928233 | W31: 0.5 | X31: 0.5 | Y31: 0.25091784 | Z31: 0.5 | AA31: 0.5 | AB31: 0.33243695 | AC31: 0.5 | AD31: 0.5 | AE31: 0.23802117 | AF31: 0.5 | AG31: 0.5 | AH31: 0.25431776 | AI31: 0.5 | AJ31: 0.5 | AK31: 0.29180793 | AL31: 0.5 | AM31: 0.5 | AN31: 0.34322011 | AO31: 0.5 | AP31: 0.5 | AQ31: 0.34167703 | AR31: 0.5 | AS31: 0.5 | AT31: 0.37307327 | AU31: 0.5 | AV31: 0.5 | AW31: 0.49119871 | AX31: 0.5
B32: 9 | L32: 0.5 | M32: 0.22163991 | N32: 0.5 | R32: 0.5 | S32: 0.22165622 | T32: 0.5 | U32: 0.5 | V32: 0.27928233 | W32: 0.5 | X32: 0.5 | Y32: 0.25091784 | Z32: 0.5 | AA32: 0.5 | AB32: 0.33243695 | AC32: 0.5 | AD32: 0.5 | AE32: 0.23802117 | AF32: 0.5 | AG32: 0.5 | AH32: 0.25431776 | AI32: 0.5 | AJ32: 0.5 | AK32: 0.29180793 | AL32: 0.5 | AM32: 0.5 | AN32: 0.34322011 | AO32: 0.5 | AP32: 0.5 | AQ32: 0.34167703 | AR32: 0.5 | AS32: 0.5 | AT32: 0.37307327 | AU32: 0.5 | AV32: 0.5 | AW32: 0.49119871 | AX32: 0.5
B33: 10 | L33: 0.5 | M33: 0.22163991 | N33: 0.5 | R33: 0.5 | S33: 0.22165622 | T33: 0.5 | U33: 0.5 | V33: 0.27928233 | W33: 0.5 | X33: 0.5 | Y33: 0.25091784 | Z33: 0.5 | AA33: 0.5 | AB33: 0.33243695 | AC33: 0.5 | AD33: 0.5 | AE33: 0.23802117 | AF33: 0.5 | AG33: 0.5 | AH33: 0.25431776 | AI33: 0.5 | AJ33: 0.5 | AK33: 0.29180793 | AL33: 0.5 | AM33: 0.5 | AN33: 0.34322011 | AO33: 0.5 | AP33: 0.5 | AQ33: 0.34167703 | AR33: 0.5 | AS33: 0.5 | AT33: 0.37307327 | AU33: 0.5 | AV33: 0.5 | AW33: 0.49119871 | AX33: 0.5
